<?xml version="1.0" encoding="utf-8"?><testsuite errors="3" failures="0" name="pytest" skipped="0" tests="3" time="6.835"><testcase classname="test_dir.test_baidu.TestSearch" file="test_dir/test_baidu.py" line="11" name="test_baidu_search_case" time="2.936"><error message="test setup failure">file /Users/huishow/PycharmProjects/pyautoTest/test_dir/test_baidu.py, line 12
      def test_baidu_search_case(self, browser, base_url):
E       fixture &apos;base_url&apos; not found
&gt;       available fixtures: adviser_account, adviser_name, audio_dir, browser, browser_close, cache, capfd, capfdbinary, caplog, capsys, capsysbinary, cases_pathh, class_name, comm_content, connect_db, course, crm_url, doctest_namespace, education_account, education_name, metadata, monkeypatch, pass_word, phonenum, pytestconfig, questions, record_property, record_testsuite_property, record_xml_attribute, recwarn, remarks, school_name, student_name, supervisor_account, tmp_path, tmp_path_factory, tmpdir, tmpdir_factory
&gt;       use &apos;pytest --fixtures [testpath]&apos; for help on them.

/Users/huishow/PycharmProjects/pyautoTest/test_dir/test_baidu.py:12</error></testcase><testcase classname="test_dir.test_baidu.TestSearch" file="test_dir/test_baidu.py" line="28" name="test_baidu_search[case1]" time="0.002"><error message="test setup failure">file /Users/huishow/PycharmProjects/pyautoTest/test_dir/test_baidu.py, line 29
      @pytest.mark.parametrize(
          &quot;name, search_key&quot;,
          [(&quot;1&quot;, &quot;Selenium&quot;),
           (&quot;2&quot;, &quot;pytest文档&quot;),
           (&quot;3&quot;, &quot;pytest-html&quot;),
           ],
           ids=[&quot;case1&quot;, &quot;case2&quot;, &quot;case3&quot;]
          )
      def test_baidu_search(self, name, search_key, browser, base_url):
E       fixture &apos;base_url&apos; not found
&gt;       available fixtures: adviser_account, adviser_name, audio_dir, browser, browser_close, cache, capfd, capfdbinary, caplog, capsys, capsysbinary, cases_pathh, class_name, comm_content, connect_db, course, crm_url, doctest_namespace, education_account, education_name, metadata, monkeypatch, pass_word, phonenum, pytestconfig, questions, record_property, record_testsuite_property, record_xml_attribute, recwarn, remarks, school_name, student_name, supervisor_account, tmp_path, tmp_path_factory, tmpdir, tmpdir_factory
&gt;       use &apos;pytest --fixtures [testpath]&apos; for help on them.

/Users/huishow/PycharmProjects/pyautoTest/test_dir/test_baidu.py:29</error></testcase><testcase classname="pytest" name="internal" time="0.000"><error message="internal error">Traceback (most recent call last):
  File &quot;/Library/Frameworks/Python.framework/Versions/3.7/lib/python3.7/site-packages/_pytest/main.py&quot;, line 213, in wrap_session
    session.exitstatus = doit(config, session) or 0
  File &quot;/Library/Frameworks/Python.framework/Versions/3.7/lib/python3.7/site-packages/_pytest/main.py&quot;, line 257, in _main
    config.hook.pytest_runtestloop(session=session)
  File &quot;/Library/Frameworks/Python.framework/Versions/3.7/lib/python3.7/site-packages/pluggy/hooks.py&quot;, line 289, in __call__
    return self._hookexec(self, self.get_hookimpls(), kwargs)
  File &quot;/Library/Frameworks/Python.framework/Versions/3.7/lib/python3.7/site-packages/pluggy/manager.py&quot;, line 87, in _hookexec
    return self._inner_hookexec(hook, methods, kwargs)
  File &quot;/Library/Frameworks/Python.framework/Versions/3.7/lib/python3.7/site-packages/pluggy/manager.py&quot;, line 81, in &lt;lambda&gt;
    firstresult=hook.spec.opts.get(&quot;firstresult&quot;) if hook.spec else False,
  File &quot;/Library/Frameworks/Python.framework/Versions/3.7/lib/python3.7/site-packages/pluggy/callers.py&quot;, line 208, in _multicall
    return outcome.get_result()
  File &quot;/Library/Frameworks/Python.framework/Versions/3.7/lib/python3.7/site-packages/pluggy/callers.py&quot;, line 80, in get_result
    raise ex[1].with_traceback(ex[2])
  File &quot;/Library/Frameworks/Python.framework/Versions/3.7/lib/python3.7/site-packages/pluggy/callers.py&quot;, line 187, in _multicall
    res = hook_impl.function(*args)
  File &quot;/Library/Frameworks/Python.framework/Versions/3.7/lib/python3.7/site-packages/_pytest/main.py&quot;, line 278, in pytest_runtestloop
    item.config.hook.pytest_runtest_protocol(item=item, nextitem=nextitem)
  File &quot;/Library/Frameworks/Python.framework/Versions/3.7/lib/python3.7/site-packages/pluggy/hooks.py&quot;, line 289, in __call__
    return self._hookexec(self, self.get_hookimpls(), kwargs)
  File &quot;/Library/Frameworks/Python.framework/Versions/3.7/lib/python3.7/site-packages/pluggy/manager.py&quot;, line 87, in _hookexec
    return self._inner_hookexec(hook, methods, kwargs)
  File &quot;/Library/Frameworks/Python.framework/Versions/3.7/lib/python3.7/site-packages/pluggy/manager.py&quot;, line 81, in &lt;lambda&gt;
    firstresult=hook.spec.opts.get(&quot;firstresult&quot;) if hook.spec else False,
  File &quot;/Library/Frameworks/Python.framework/Versions/3.7/lib/python3.7/site-packages/pluggy/callers.py&quot;, line 208, in _multicall
    return outcome.get_result()
  File &quot;/Library/Frameworks/Python.framework/Versions/3.7/lib/python3.7/site-packages/pluggy/callers.py&quot;, line 80, in get_result
    raise ex[1].with_traceback(ex[2])
  File &quot;/Library/Frameworks/Python.framework/Versions/3.7/lib/python3.7/site-packages/pluggy/callers.py&quot;, line 187, in _multicall
    res = hook_impl.function(*args)
  File &quot;/Library/Frameworks/Python.framework/Versions/3.7/lib/python3.7/site-packages/pytest_rerunfailures.py&quot;, line 176, in pytest_runtest_protocol
    reports = runtestprotocol(item, nextitem=nextitem, log=False)
  File &quot;/Library/Frameworks/Python.framework/Versions/3.7/lib/python3.7/site-packages/_pytest/runner.py&quot;, line 81, in runtestprotocol
    rep = call_and_report(item, &quot;setup&quot;, log)
  File &quot;/Library/Frameworks/Python.framework/Versions/3.7/lib/python3.7/site-packages/_pytest/runner.py&quot;, line 169, in call_and_report
    report = hook.pytest_runtest_makereport(item=item, call=call)
  File &quot;/Library/Frameworks/Python.framework/Versions/3.7/lib/python3.7/site-packages/pluggy/hooks.py&quot;, line 289, in __call__
    return self._hookexec(self, self.get_hookimpls(), kwargs)
  File &quot;/Library/Frameworks/Python.framework/Versions/3.7/lib/python3.7/site-packages/pluggy/manager.py&quot;, line 87, in _hookexec
    return self._inner_hookexec(hook, methods, kwargs)
  File &quot;/Library/Frameworks/Python.framework/Versions/3.7/lib/python3.7/site-packages/pluggy/manager.py&quot;, line 81, in &lt;lambda&gt;
    firstresult=hook.spec.opts.get(&quot;firstresult&quot;) if hook.spec else False,
  File &quot;/Library/Frameworks/Python.framework/Versions/3.7/lib/python3.7/site-packages/pluggy/callers.py&quot;, line 203, in _multicall
    gen.send(outcome)
  File &quot;/Users/huishow/PycharmProjects/pyautoTest/conftest.py&quot;, line 250, in pytest_runtest_makereport
    capture_screenshot(case_name)
  File &quot;/Users/huishow/PycharmProjects/pyautoTest/conftest.py&quot;, line 297, in capture_screenshot
    driver.save_screenshot(image_dir)
  File &quot;/Library/Frameworks/Python.framework/Versions/3.7/lib/python3.7/site-packages/selenium/webdriver/remote/webdriver.py&quot;, line 1055, in save_screenshot
    return self.get_screenshot_as_file(filename)
  File &quot;/Library/Frameworks/Python.framework/Versions/3.7/lib/python3.7/site-packages/selenium/webdriver/remote/webdriver.py&quot;, line 1032, in get_screenshot_as_file
    png = self.get_screenshot_as_png()
  File &quot;/Library/Frameworks/Python.framework/Versions/3.7/lib/python3.7/site-packages/selenium/webdriver/remote/webdriver.py&quot;, line 1064, in get_screenshot_as_png
    return base64.b64decode(self.get_screenshot_as_base64().encode(&apos;ascii&apos;))
  File &quot;/Library/Frameworks/Python.framework/Versions/3.7/lib/python3.7/site-packages/selenium/webdriver/remote/webdriver.py&quot;, line 1074, in get_screenshot_as_base64
    return self.execute(Command.SCREENSHOT)[&apos;value&apos;]
  File &quot;/Library/Frameworks/Python.framework/Versions/3.7/lib/python3.7/site-packages/selenium/webdriver/remote/webdriver.py&quot;, line 321, in execute
    self.error_handler.check_response(response)
  File &quot;/Library/Frameworks/Python.framework/Versions/3.7/lib/python3.7/site-packages/selenium/webdriver/remote/errorhandler.py&quot;, line 242, in check_response
    raise exception_class(message, screen, stacktrace)
selenium.common.exceptions.WebDriverException: Message: chrome not reachable
  (Session info: chrome=75.0.3770.100)</error></testcase></testsuite>